Workbook
Name Excel_BuiltIn_Print_Area: 'Front Page'!$A$1:$BL$114
Name Excel_BuiltIn_Print_Area: 'Personal Info'!$A$1:$BL$95

Sheet Front Page
A1: How to use this sheet! READ. EVERY. PAGE. FIRST. Much of this is automated; if you read the pages first, you should have an easier time of not cocking this up. Gray Cells contain formula which will automatically reference the necessary areas, so, DO NOT TOUCH THEM. Make sure to use a ' before anything with a mathmatical symbol infront of it, + - / *, otherwise it will think you're trying to do maths and will barf with text. Red Cells are a head's up.
B3: CHARACTER: | I3: Aranaea | AI3: PLAYER:
B6: BACKGROUND: | I6: Outer Colonial
AI7: Eclipse | AP7: CHARACTER SHEET
B9: FACTION: | I9: Terran | AI9: Phase
AR11: APTITUDES:
B12: Species/Morph: | I12: ='Species & Traits'!I77 -> Arachnoid | BF12: 105 | BJ12: POINTS
AR13: COG | AU13: COO | AX13: INT | BA13: REF | BD13: SAV | BG13: SOM | BJ13: WILL | BM13: =sum(AR15:BL15) -> 110
B15: Gender Identity: | AK15: Base Aptitudes: | AR15: 20 | AU15: 20 | AX15: 20 | BA15: 15 | BD15: 5 | BG15: 20 | BJ15: 10
AK16: Racial Bonus: | AR16: ='Species & Traits'!AX83 | AU16: ='Species & Traits'!AZ83 -> 5 | AX16: ='Species & Traits'!BB83 | BA16: ='Species & Traits'!BD83 | BD16: ='Species & Traits'!BF83 | BG16: ='Species & Traits'!BH83 -> 10 | BJ16: ='Species & Traits'!BJ83
B18: Actual Age: | AK18: Total: | AR18: =AR15+AR16 -> 20 | AU18: =AU15+AU16 -> 25 | AX18: =AX15+AX16 -> 20 | BA18: =BA15+BA16 -> 15 | BD18: =BD15+BD16 -> 5 | BG18: =BG15+BG16 -> 30 | BJ18: =BJ15+BJ16 -> 10
AK19: Aptitude Max: | AP19: =sum('Species & Traits'!B92) -> 30 | BM19: =IF(BN19<BF12,0,BN19*10-BF12*10) -> 50 | BN19: =SUM(AR15:BL15) -> 110
B21: Current Moxie Points: | L21: 2 | P21: Permanent Moxie Points: | Z21: 2 | AS21: Psychic? | BB21: Vitals and Statistics:
AW23: WIL x2 | BC23: From Morph | BF23: (INT+REF)/5
B24: Character Points: | G24: 1000 | L24: Resolution Points: | Q24: 5 | V24: Available Points: | AA24: =G24+Q24-AE38 -> 5
AS25: MOX | AU25: TT | AW25: LUC | AY25: IR | BA25: WT | BC25: DUR | BE25: DR | BG25: INIT | BI25: SPD | BK25: DAM+
B27: Motivations: Pro = '+ Anti = - | I27: `+ Exploration | AS27: =L21 -> 2 | AU27: =IF(AW21="Novice",ROUNDDOWN((AW27/5)-1,0),IF(AW21="Practicing",ROUNDDOWN((AW27/5)-1,0),IF(AW21="Master",ROUNDDOWN((AW27/5)-1,0),ROUNDDOWN(AW27/5,0)))) -> 4 | AW27: =BJ18*2 -> 20 | AY27: =AW27*2 -> 40 | BA27: =ROUNDDOWN(BC27/5,0) -> 11 | BC27: ='Species & Traits'!F97 -> 55 | BE27: =IF('Species & Traits'!AP78="Monstrous",BC27*2,ROUND(BC27*1.5,0)) -> 83 | BG27: =sum(AX18+BA18)/5+'Species & Traits'!B97 -> 7 | BI27: ='Species & Traits'!I92+1 -> 1 | BK27: =ROUND(BG18/5,0) -> 6
AU29: LUC /5 | AY29: LUC x2 | BA29: DUR /5 | BD29: Normal: DUR x1.5 Synthetic: DUR x2.0 | BK29: SOM /5
AF31: Armor Notes: | AS31: Penalty Mitigators: | BA31: 3
BA33: Wounds | BC33: Trauma | BE33: DAMAGE & STRESS | BM33: =BJ36-BC31 -> 0 | BN33: =BD36-BA31 -> -3
J34: Nat: | L34: Under: | N34: Outer: | P34: Mod: | R34: Energy | U34: Nat: | W34: Under: | Y34: Outer: | AA34: Mod: | AC34: Kinetic | BM34: =IF(BM33<0,0,BM33) -> 0 | BN34: =IF(BN33<0,0,BN33) -> 0
B35: Armor(Worn): | J35: 14 | P35: 2 | R35: =SUM(P35+N35+L35+J35+J37) -> 16 | U35: 12 | AC35: =SUM(AA35+Y35+W35+U35+O37) -> 12 | BA35: DAMAGE | BD35: WOUNDS | BG35: STRESS | BJ35: TRAUMA
B37: Armor(Held): | M37: / | R37: Armor Penalty: | AB37: =ROUND(Ledger!AG12,0) -> 0 | AE37: =SUM('Species & Traits'!A12+Ledger!AG20) -> 79
AB38: =SUM(BM19+A45+A87+A88+A89+A90+A91+A92+AG47) -> 921 | AE38: =SUM(AB38+AE37) -> 1000 | BA38: Wound/Trauma Penalties: | BG38: =SUM(BM34+BN34)*-10 -> 0
J39: Energy | O39: Kinetic | Z39: Worn | AC39: Held
B40: Primary Weapon:
K42: WEAPON | T42: SKILL | AB42: DV: | AG42: AP: | AL42: Modes: | AS42: Short: | AX42: Medium: | BC42: Long: | BH42: Extreme:
A45: =SUM(A46:A48)*5 -> 5 | B45: Notes:
A46: =countif(AC49:AC86,"*") -> 0 | N46: 400 | Q46: RP Spent -> | U46: =sum(A90:A92) -> 0 | Y46: CP Spent -> | AC46: =sum(A87:A88) -> 511
A47: =countif(BI49:BI62,"*") -> 1 | B47: ACTIVE SKILLS | J47: ATTRIBUTE | M47: RZ POINTS | P47: SKILL POINTS | S47: Morph Bonus: | V47: TOTAL | Y47: OTHER BONUSES | AC47: SPECIALIZATION | AG47: =SUM((Z21-1)*15) -> 15 | AH47: ACTIVE SKILLS | AP47: ATTRIBUTE | AS47: RZ POINTS | AV47: SKILL POINTS | AY47: Morph Bonus: | BB47: TOTAL | BE47: OTHER BONUSES | BI47: SPECIALIZATION | BM47: =ROUND(Ledger!AG12,0) -> 0
A48: =countif(BI67:BI86,"*") -> 0
A49: =M49+P49+S49+Y49+V49 -> 5 | B49: Animal Handling | J49: SAV | V49: =IF(J49="COG",AR18,IF(J49="COO",AU18,IF(J49="INT",AX18,IF(J49="REF",BA18+BN65,IF(J49="SAV",BD18,IF(J49="SOM",BG18+BN65,IF(J49="WILL",BJ18,0))))))) -> 5 | W49: =IF(A49>60,A49-BM49,A49) -> 5 | AG49: =AS49+AV49+AY49+BE49+BB49 -> 15 | AH49: Pilot: (flight) | AP49: REF | BB49: =IF(AP49="COG",AR18,IF(AP49="COO",AU18,IF(AP49="INT",AX18,IF(AP49="REF",BA18+BN65,IF(AP49="SAV",BD18,IF(AP49="SOM",BG18+BN65,IF(AP49="WILL",BJ18,0))))))) -> 15 | BC49: =IF(AG49>60,AG49-BN49,AG49) -> 15 | BM49: =IF(A49>60,SUM((A49-60)/2),0) -> 0 | BN49: =IF(AG49>60,SUM((AG49-60)/2),0) -> 0
A50: =M50+P50+S50+Y50+V50 -> 30 | B50: Beam Weapons | J50: COO | V50: =IF(J50="COG",AR18,IF(J50="COO",AU18,IF(J50="INT",AX18,IF(J50="REF",BA18+BN65,IF(J50="SAV",BD18,IF(J50="SOM",BG18+BN65,IF(J50="WILL",BJ18,0))))))) -> 25 | W50: =IF(A50>60,A50-BM50,A50) -> 30 | Y50: 5 | AG50: =AS50+AV50+AY50+BE50+BB50 -> 15 | AH50: Pilot: (ground) | AP50: REF | BB50: =IF(AP50="COG",AR18,IF(AP50="COO",AU18,IF(AP50="INT",AX18,IF(AP50="REF",BA18+BN65,IF(AP50="SAV",BD18,IF(AP50="SOM",BG18+BN65,IF(AP50="WILL",BJ18,0))))))) -> 15 | BC50: =IF(AG50>60,AG50-BN50,AG50) -> 15 | BM50: =IF(A50>60,SUM((A50-60)/2),0) -> 0 | BN50: =IF(AG50>60,SUM((AG50-60)/2),0) -> 0
A51: =M51+P51+S51+Y51+V51 -> 50 | B51: Blades | J51: SOM | P51: 20 | V51: =IF(J51="COG",AR18,IF(J51="COO",AU18,IF(J51="INT",AX18,IF(J51="REF",BA18+BN65,IF(J51="SAV",BD18,IF(J51="SOM",BG18+BN65,IF(J51="WILL",BJ18,0))))))) -> 30 | W51: =IF(A51>60,A51-BM51,A51) -> 50 | AG51: =AS51+AV51+AY51+BE51+BB51 -> 35 | AH51: Programming | AP51: COG | AV51: 15 | BB51: =IF(AP51="COG",AR18,IF(AP51="COO",AU18,IF(AP51="INT",AX18,IF(AP51="REF",BA18+BN65,IF(AP51="SAV",BD18,IF(AP51="SOM",BG18+BN65,IF(AP51="WILL",BJ18,0))))))) -> 20 | BC51: =IF(AG51>60,AG51-BN51,AG51) -> 35 | BM51: =IF(A51>60,SUM((A51-60)/2),0) -> 0 | BN51: =IF(AG51>60,SUM((AG51-60)/2),0) -> 0
A52: =M52+P52+S52+Y52+V52 -> 50 | B52: Climbing | J52: SOM | P52: 20 | V52: =IF(J52="COG",AR18,IF(J52="COO",AU18,IF(J52="INT",AX18,IF(J52="REF",BA18+BN65,IF(J52="SAV",BD18,IF(J52="SOM",BG18+BN65,IF(J52="WILL",BJ18,0))))))) -> 30 | W52: =IF(A52>60,A52-BM52,A52) -> 50 | AG52: =AS52+AV52+AY52+BE52+BB52 -> 15 | AH52: Protocol | AP52: SAV | AV52: 10 | BB52: =IF(AP52="COG",AR18,IF(AP52="COO",AU18,IF(AP52="INT",AX18,IF(AP52="REF",BA18+BN65,IF(AP52="SAV",BD18,IF(AP52="SOM",BG18+BN65,IF(AP52="WILL",BJ18,0))))))) -> 5 | BC52: =IF(AG52>60,AG52-BN52,AG52) -> 15 | BM52: =IF(A52>60,SUM((A52-60)/2),0) -> 0 | BN52: =IF(AG52>60,SUM((AG52-60)/2),0) -> 0
A53: =M53+P53+S53+Y53+V53 -> 30 | B53: Clubs | J53: SOM | V53: =IF(J53="COG",AR18,IF(J53="COO",AU18,IF(J53="INT",AX18,IF(J53="REF",BA18+BN65,IF(J53="SAV",BD18,IF(J53="SOM",BG18+BN65,IF(J53="WILL",BJ18,0))))))) -> 30 | W53: =IF(A53>60,A53-BM53,A53) -> 30 | AG53: =AS53+AV53+AY53+BE53+BB53 -> 10 | AH53: Psi Assault(PSI)* | AP53: WILL | BB53: =IF(AP53="COG",AR18,IF(AP53="COO",AU18,IF(AP53="INT",AX18,IF(AP53="REF",BA18+BN65,IF(AP53="SAV",BD18,IF(AP53="SOM",BG18+BN65,IF(AP53="WILL",BJ18,0))))))) -> 10 | BC53: =IF(AG53>60,AG53-BN53,AG53) -> 10 | BM53: =IF(A53>60,SUM((A53-60)/2),0) -> 0 | BN53: =IF(AG53>60,SUM((AG53-60)/2),0) -> 0
A54: =M54+P54+S54+Y54+V54 -> 10 | B54: Control(PSI)* | J54: WILL | V54: =IF(J54="COG",AR18,IF(J54="COO",AU18,IF(J54="INT",AX18,IF(J54="REF",BA18+BN65,IF(J54="SAV",BD18,IF(J54="SOM",BG18+BN65,IF(J54="WILL",BJ18,0))))))) -> 10 | W54: =IF(A54>60,A54-BM54,A54) -> 10 | AG54: =AS54+AV54+AY54+BE54+BB54 -> 20 | AH54: Psychosurgery | AP54: INT | BB54: =IF(AP54="COG",AR18,IF(AP54="COO",AU18,IF(AP54="INT",AX18,IF(AP54="REF",BA18+BN65,IF(AP54="SAV",BD18,IF(AP54="SOM",BG18+BN65,IF(AP54="WILL",BJ18,0))))))) -> 20 | BC54: =IF(AG54>60,AG54-BN54,AG54) -> 20 | BM54: =IF(A54>60,SUM((A54-60)/2),0) -> 0 | BN54: =IF(AG54>60,SUM((AG54-60)/2),0) -> 0
A55: =M55+P55+S55+Y55+V55 -> 15 | B55: Deception | J55: SAV | P55: 10 | V55: =IF(J55="COG",AR18,IF(S18="COO",AU18,IF(J55="INT",AX18,IF(J55="REF",BA18+BN65,IF(J55="SAV",BD18,IF(J55="SOM",BG18+BN65,IF(J55="WILL",BJ18,0))))))) -> 5 | W55: =IF(A55>60,A55-BM55,A55) -> 15 | AG55: =AS55+AV55+AY55+BE55+BB55 -> 40 | AH55: Research | AP55: COG | AV55: 20 | BB55: =IF(AP55="COG",AR18,IF(AP55="COO",AU18,IF(AP55="INT",AX18,IF(AP55="REF",BA18+BN65,IF(AP55="SAV",BD18,IF(AP55="SOM",BG18+BN65,IF(AP55="WILL",BJ18,0))))))) -> 20 | BC55: =IF(AG55>60,AG55-BN55,AG55) -> 40 | BM55: =IF(A55>60,SUM((A55-60)/2),0) -> 0 | BN55: =IF(AG55>60,SUM((AG55-60)/2),0) -> 0
A56: =M56+P56+S56+Y56+V56 -> 50 | B56: Demolitions | J56: COG | P56: 30 | V56: =IF(J56="COG",AR18,IF(J56="COO",AU18,IF(J56="INT",AX18,IF(J56="REF",BA18+BN65,IF(J56="SAV",BD18,IF(J56="SOM",BG18+BN65,IF(J56="WILL",BJ18,0))))))) -> 20 | W56: =IF(A56>60,A56-BM56,A56) -> 50 | AG56: =AS56+AV56+AY56+BE56+BB56 -> 60 | AH56: Scrounging | AP56: INT | AV56: 30 | BB56: =IF(AP56="COG",AR18,IF(AP56="COO",AU18,IF(AP56="INT",AX18,IF(AP56="REF",BA18+BN65,IF(AP56="SAV",BD18,IF(AP56="SOM",BG18+BN65,IF(AP56="WILL",BJ18,0))))))) -> 20 | BC56: =IF(AG56>60,AG56-BN56,AG56) -> 60 | BE56: 10 | BI56: ruins | BM56: =IF(A56>60,SUM((A56-60)/2),0) -> 0 | BN56: =IF(AG56>60,SUM((AG56-60)/2),0) -> 0
A57: =M57+P57+S57+Y57+V57 -> 25 | B57: Disguise | J57: INT | P57: 5 | V57: =IF(J57="COG",AR18,IF(J57="COO",AU18,IF(J57="INT",AX18,IF(J57="REF",BA18+BN65,IF(J57="SAV",BD18,IF(J57="SOM",BG18+BN65,IF(J57="WILL",BJ18,0))))))) -> 20 | W57: =IF(A57>60,A57-BM57,A57) -> 25 | AG57: =AS57+AV57+AY57+BE57+BB57 -> 25 | AH57: Seeker Weapons | AP57: COO | BB57: =IF(AP57="COG",AR18,IF(AP57="COO",AU18,IF(AP57="INT",AX18,IF(AP57="REF",BA18+BN65,IF(AP57="SAV",BD18,IF(AP57="SOM",BG18+BN65,IF(AP57="WILL",BJ18,0))))))) -> 25 | BC57: =IF(AG57>60,AG57-BN57,AG57) -> 25 | BM57: =IF(A57>60,SUM((A57-60)/2),0) -> 0 | BN57: =IF(AG57>60,SUM((AG57-60)/2),0) -> 0
...

Sheet Species & Traits
B2: CHARACTER: | I2: ='Front Page'!I3 -> Aranaea | AI2: PLAYER: | AP2: ='Front Page'!AP3
A4: Reputation: | F4: Rating: | I4: Details of who/where | Q4: Base Rep: | T4: 50 | V4: Rating: | Y4: Details of who/where | AI4: FANTASY | AP4: CHARACTER SHEET
A5: =SUM(F5+F8+F11+F14+V5+V8+V11+V14)-(T4+U16) -> -50 | B5: Terran Acclaim | R5: HSE Esteem
A6: =IF(A5<0,0,A5/10) -> 0 | AI6: PHASE
A7: =Y77 -> 45
A8: =SUM(AD17:AE50) -> 10 | B8: Street Cred | R8: Morningstar Acclaim | BI8: CP/RP Cost:
A9: =SUM(BK9:BL50) -> 0 | AI9: PSI Sleights:
A10: =SUM(BK54:BL71) -> 0
A11: =SUM(BG103:BL116) -> 0 | B11: Peoples' Acclaim | R11: StelComm Airtime
A12: =SUM(A6:A10) -> 55
B14: Research Points
Q16: Bonus Rep: | AB16: CP/RP Cost:
B17: Positive & Negative Traits, Extra Abilities:
B19: Tough, +5 durability, +1 wound | AD19: 10
B52: Miscellaneous: | BI52: CP/RP Cost:
B74: CHARACTER: | I74: =I2 -> Aranaea | AI74: FANTASY
AI76: PHASE
B77: Race/Morph: | I77: Arachnoid | V77: CP Cost: | Y77: 45
AI78: Type(Bio/Synth): | AP78: Synth
AX79: APTITUDE BONUSES
B80: Sex / Visible Gender:
AI81: High G? | AX81: COG | AZ81: COO | BB81: INT | BD81: REF | BF81: SAV | BH81: SOM | BJ81: WILL
B83: Apparent Age/ Actual Age: | AP83: Racial Bonuses: | AZ83: 5 | BH83: 10
AQ85: Note: Include Profession/Background/Other bonuses here
B86: Description:
AI87: Racial Biological Traits / Advantages & Disadvantages:
B90: APTITUDE MAX: | I90: SPD Mod from All Sources: | P90: MOVEMENT RATE & TYPES:
B92: 30 | P92: walker 4/24
P94: Thrust Vector 8/40
B95: Init+: | F95: DURABILITY:
P96: Wheeled 8/40
F97: 55
B101: Additional Biological Traits, Surgical, Alchemical and Exceptional Alterations: | BI101: Credit Cost:
B103: Access Jacks, Basic Mesh Inserts, Cortical Stack, Cyberbrain, Enhanced Vision, Extra Limbs (10), Lidar, Mnemonic Augmentation, Pneumatic Limbs, Radar

Sheet Personal Info
A1: Description:
A15: History:
A37: Journal In Brief:

Sheet Ledger
P1: Ledger Balance, Services Paid and Equipment Owned
A2: Starting Coffer: | F2: 5000 | L2: Credits | BA2: Trivial | BF2: 50
A3: Pay for Services: | J3: Credits Spent: | Q3: =AG14+AG15+AG16+'Species & Traits'!A11 -> 19850 | U3: Weight of Carried Goods: | AB3: Somatics Modifier of Worn/Used Equipment: | BA3: Low | BF3: 250
J4: CP Required: | Q4: =IF(AG19<0,SUM(AG19*-0.001),0) -> 0 | BA4: Moderate | BF4: 1000
A5: Liquidity: | F5: =SUM((Q5*1000)+(F2+F3))-Q3 -> 9150 | L5: CP Set Aside: | Q5: 24 | U5: =CONCATENATE(AG10+AG11," kg") -> 0 kg | BA5: High | BF5: 5000
BA6: Expensive | BF6: 20000
A7: Equipped/Carried Goods and Items: | AG7: Equipped/Carried Goods and Items:
A9: Item: | AA9: Weight(kg): | AD9: Cost: | AG9: =IF('Species & Traits'!AP81="Yes",SUM((AG18+AK3)*1),SUM((AG18+AK3)*0.5)) -> 15 | AH9: Item: | BH9: Weight(kg): | BK9: Cost:
A10: Light Combat Armor 14/12, Chameleon coating +30 visual stealth, fireproofing, +2/+0 +10 vs fire, self healing, shock proof +10 vs shocks, Thermal Dampening, +30 against thermal spotting | AC10: 2600 | AG10: =SUM(AA10:AB39) -> 0 | AH10: Access Jacks, Basic Mesh Inserts, Cortical Stack, Cyberbrain, Enhanced Vision, Extra Limbs (10), Lidar, Mnemonic Augmentation, Radar
AG11: =SUM(BH10:BI38) -> 0
A12: Fractal Digits, +20 coo for fine manipulation | AC12: 1000 | AG12: =IF(AG18<0.01,0,SUM(AG13*-1)) -> 0
AG13: =IF(AG10+AG11>0.001,SUM((AG10+AG11)/AG9),0) -> 0
A14: Hidden Compartment | AC14: 250 | AG14: =SUM(AC10:AF57) -> 11850 | AH14: Cyberclaws | BJ14: 250
AG15: =SUM(BJ10:BM57) -> 8000
A16: Magnetic System, +30 when holding onto something magnetic | AC16: 250 | AG16: =SUM(BI72:BM115) -> 0 | AH16: implanted nanotoxin (necrosis) | BJ16: 5000
A18: Pneumatic Limbs, +20 Freerunning, +1d10 melee damage | AC18: free | AG18: =SUM('Front Page'!BG18) -> 30
AG19: =SUM((Q5*1000)+F2)-Q3 -> 9150
A20: Structural Enhancement, +10 dur, +2 wound | AC20: 1000 | AG20: =SUM(Q5+Q4) -> 24 | AH20: Utilitool | BJ20: 250
A22: weapon mount, concealed, articulated | AC22: 1000 | AH22: Viewer | BJ22: 250
A24: 360 vision | AC24: 250 | AH24: Electronic rope (200 ft) | BJ24: 1000
A26: Chemichal Sniffer | AC26: 1000 | AH26: spindle and climber | BJ26: 1250
A28: Lidar | AC28: free
A30: Nanoscopic Vision | AC30: 1000
A32: Radar | AC32: Free
A34: Fiber Eye | AC34: 250
A36: Traction Pads | AC36: 250
A38: X-ray Emmitter | AC38: 250
A40: Direction sense, echolocation, enhanced hearing, enhanced smell | AC40: 1000
A42: Math Boost | AC42: 250
A44: eelware | AC44: 250
A46: laser/microwave link | AC46: 1000
A48: radio booster | AC48: 250
A70: Owned Goods/Properties and Services Procured: | AV70: Location: | BE70: Cost:

Sheet Combat Info
A1: Combat Modifiers (p. 193) | AA1: Firing Modes (p. 198) | BB1: Charging (Melee) (p. 197)
A2: General | Q2: Mod | AA2: Single Shot (SS) | AJ2: 1 shot | BB2: Charge | BF2: -10 running, +1d10DV melee.
A3: Using off-hand | Q3: -20 | AA3: Semi-Automatic (SA) | AJ3: 2 shots, 2 separate attacks | BB3: Receive | BF3: If delaying action, +20 attacking charging opponent.
A4: Wounded | Q4: -10/wound | AA4: Burst Fire (BF) | AJ4: 3 shots/burst, 2 bursts. Can hit 2 targets 1 meter apart. If 1 target, +1d10DV.
A5: Traumatized | Q5: -10/wound | BB5: Knockback/Knockdown (Melee) (p. 202)
A6: Superior position | Q6: +20 | AA6: Full Auto (FA) | AJ6: 10 shots, 1 attack. Can hit 3 targets each 1 meter apart. If 1 target, +1d10+10DV. | BB6: Knockback | BH6: Attack. 1 meter/MoS 10. Normal DV if critical.
A7: Touch-only attack | Q7: +20 | BB7: Knockdown | BH7: Attack. MoS 30+. Normal DV if critical.
A8: Called shot | Q8: -10
A9: Wielding 2-H weapon with one hand | Q9: -20 | AA9: Suppressive Fire (p. 204) | BB9: Subdual (Melee) (p. 204)
A10: Very small target (mouse or insect) | Q10: -30 | AA10: FA mode, 20 shots. Lasts until char's next action turn. 20 meter wide cone. Chars in open or moving out from cover of firing range get attacked by single shot. | BB10: Attack with melee skill MoS 30+. Choose to do DV if critical. Grappled may communicate or use mental skills/mesh. -30 physical actions. Free Opposed Unarmed Combat or SOM x3.
A11: Small target (child-sized) | Q11: -10
A12: Large target (car sized) | Q12: +10
A13: Very large target (side of a barn) | Q13: +30
A14: Visibility impaired (minor) | Q14: -10 | AA14: Attack Multiple Targets (p. 202) | BB14: Shock (biomoprhs/pods) (p. 204)
A15: Visibility impaired (major) | Q15: -20 | AA15: Melee | AE15: Declare up to 3 targets ea 1 meter apart. -20/target. | BB15: DUR (current) + E Armor Test. Fail = Fall and incapacitiated for 1 action turn/MoF (min 3). Afterward, -30/-20/-10 for 1 minute each. Success = half DV -30/-20/-10 for each action turn. If hit again, not cumulative, boost shock levels to max.
A16: Blind attack | Q16: -30 | AA16: Ranged | AE16: -20 2nd target for sa and bf if targets > 1 meter apart.
A17: Melee | Q17: Mod
A18: Reach advantage | Q18: +10 | AA18: Attack with Multiple Weapons (p. 206)
A19: Character charging | Q19: -10 | AA19: Melee | AE19: If same target, +1d10DV for each additional weapon (max 3d10). Treat as 1 attack.
A20: Receiving a charge | Q20: +20 | BB20: >>> MoS DAMAGE BONUS (p. 192) <<<
A21: Ranged | Q21: Mod | AA21: Ranged | AE21: Can fire all at 1 target. Add -20/weapon after 1st. | BB21: On successful hit (melee or ranged), deal extra damage if exceed MoS. | BR21: MoS 30+ | BW21: +5 DV
A22: Attacker using smartlink/laser sight | Q22: +10 | BR22: MoS 60+ | BW22: +10 DV
A23: Attacker behind cover | Q23: -10 | AA23: Called Shot (-10 mod, MoS 30+) (p. 197)
A24: Attacker running | Q24: -20 | AA24: Bypassing Armor | AI24: Ignore armor rating. | BB24: Full Defense (p. 198)
A25: Attacker in melee combat | Q25: -30 | AA25: Disarming | AI25: Half DV. Make SOM x3 -30 or drop weapon. | BB25: +30 against all attacks. May use Freerunning or Fray.
A26: Defender has minor cover | Q26: -10 | AA26: Specifying Target | AI26: GM decides.
A27: Defender has moderate cover | Q27: -20 | BB27: Physical Aptitude Tests (p. 175)
A28: Defender has major cover | Q28: -30 | AA28: Grenades/Seekers (p. 199) | BB28: Test | BP28: Roll
A29: Defender prone and far (10+ meters) | Q29: -10 | AA29: Airburst | AJ29: Explode when traveled distance. | BB29: Brute Strength | BP29: SOM x3
A30: Defender hidden | Q30: -60 | AA30: Impact | AJ30: Explode on impact. | BB30: Catching Thrown Object | BP30: COO x2 + REF
A31: Aimed shot (quick) | Q31: +10 | AA31: Signal | AJ31: Explode when signal received. | BB31: Escape Artist | BP31: COO + SOM
A32: Aimed shot (complex) | Q32: +30 | AA32: Timer | AJ32: Explode when timer runs out. 1 second delay = 1 action phase.
A33: Sweeping fire with beam weapon | Q33: +10 on second shot | BB33: Other Combat-Related Topics
A34: Multiple targets in same Action Phase | Q34: -20/additional target | AA34: Throw grenade back | AJ34: COO x2 + REF | BB34: Topic | BH34: Page | BM34: Topic | BV34: Page
A35: Indirect fire | Q35: -30 | AA35: Jump on grenade | AJ35: COO + REF + WIL or WIL x3 to fall on grenade. +1d10DV when explode. Reduce DV to others by armor +10. | BB35: Asphyxiation | BH35: p. 194 | BM35: Improvised Weapons | BV35: p. 202
A36: Point-blank range (2 meters or less) | Q36: +10 | BB36: Blind Attack | BH36: p. 195 | BM36: Indirect Fire | BV36: p. 195
A37: Short range | Q37: +0 | BB37: Demolitions | BH37: p. 197 | BM37: Objects/Structures | BV37: p. 202
A38: Medium range | Q38: -10 | AA38: Scatter (p. 204) | BB38: Falling | BH38: p. 197 | BM38: Surprise Attack | BV38: p. 204
A39: Long range | Q39: -20 | AA39: If miss with blast weapon, d10 to determine direction. Number determines distance in meters. MoF 30+ double, MoF 60+ triple. | BB39: Fire | BH39: p. 198 | BM39: Tactical Networks | BV39: p. 205
A40: Extreme range | Q40: -30 | BB40: Gravity | BH40: p. 198 | BM40: Weapon Range | BV40: p. 203
...

Sheet Other Info
A1: Moxie (p. 122) | U1: Stress Test (p. 214) | AT1: Movement (Earth's Gravity) (p. 190)
A2: Ignore mods for test. Spent before dice rolled. | U2: WIL x3. Fail = SV XP chart. Success = Hardening. | AT2: Type | BA2: Action | BE2: Meters/Action Turn | BM2: Notes
A3: Flip-flop a d100 roll result. 83 becomes 38. | AT3: Walk | BA3: Quick | BE3: 4
A4: Upgrade a success to critical success. | U4: Stress Values (p. 215) | AT4: Run | BA4: Quick | BE4: 20 | BM4: -10 all actions
A5: Downgrade critical failure, to regular failure. | U5: Situation | AO5: SV (RD) | AT5: Sprint | BA5: Complex | BE5: 5 | BM5: Freerunning (+1m/10 MoS, max 5)
A6: Go first for action phase, but after crits. | U6: Failing horribly in pursuit of motivational goal | AO6: 1d10/2 | AT6: Jump (Standing) | BA6: Complex | BE6: SOM/20 (RU) | BM6: Freerunning (+0.25m/10 MoS)
U7: Helplessness | AO7: 1d10/2 | AT7: Jump (Running) | BA7: Complex | BE7: SOM/5 (RU) | BM7: Freerunning (+1m/MoS)
A8: Networking Mods (p. 287) | U8: Betrayal by trusted friend | AO8: 1d10/2 | AT8: Jump (Vertical) | BA8: Complex | BE8: 1 | BM8: Freerunning (+0.25m/10 MoS)
A9: Situation | N9: Mod | U9: Extended isolation | AO9: 1d10/2 | AT9: Swim | BA9: Complex | BE9: 1
A10: Favor level exceeds rep level | N10: -10 per level | U10: Extreme violence (viewing) | AO10: 1d10/2 | AT10: Crawl | BA10: Complex | BE10: 1
A11: Rep level exceeds favor level | N11: +10 per level | U11: Extreme violence (committing) | AO11: 1d10
A12: Keeping quiet | N12: -variable | U12: Awareness that your death is imminent | AO12: 1d10 | AT12: What Your Muse Can Do For You (p. 245)
A13: Burning rep | N13: +rep burned | U13: Experiencing someone’s death via XP | AO13: 1d10 | AT13: Make Research Tests to find information for you.
A14: Paying extra | N14: +10 per level | U14: Losing loved one | AO14: 1d10/2 | AT14: Scan newsfeeds and mesh updates for keyword alerts.
U15: Watching loved one die | AO15: 1d10+2 | AT15: Monitor your mesh inserts/ecto/PAN and slaved devices for intrusion.
A16: Ectos (p. 246) | U16: Being responsible for death of loved one | AO16: 1d10+5 | AT16: Launch countermeasures against intruders.
A17: -10 when rushed (combat/pressure) 25% long for task actions. | U17: Encountering gruesome murder scene | AO17: 1d10 | AT17: Teleoperate and command robots.
U18: Torture (viewing) | AO18: 1d10+2 | AT18: Monitor your Rep score and alert you to drastic changes.
U19: Torture (moderate suffering) | AO19: 2d10+3 | AT19: Automatically provide feedback for other people’s Rep scores.
A20: Resleeving (p. 271) | U20: Torture (severe suffering) | AO20: 3d10+5 | AT20: Run audio input through an online, real-time language translation system.
A21: Test | G21: Roll | U21: Encountering aliens (non-sentient) | AO21: 1d10/2 | AT21: Put you in privacy mode and/or proactively stealth your wireless signal.
A22: Integration | G22: SOM * 3 + mods (see chart) | U22: Encountering aliens (sentient) | AO22: 1d10 | AT22: Falsify/fluctuate your mesh ID.
A23: Alienation | G23: INT * 3 + mods (see chart) | U23: Encountering hostile aliens | AO23: 1d10+3 | AT23: Track people for you.
A24: Continuity | G24: WIL * 3 (see stress chart) | U24: Encountering highly-advanced technology | AO24: 1d10/2 | AT24: Anticipate your needs and act accordingly, pre-empting your requests.
A25: Forks | G25: See page 273. | U25: Encountering Exsurgent-modified technology | AO25: 1d10/2
A26: Merging | G26: See page 275. | U26: Encountering Exsurgent-infected transhumans | AO26: 1d10 | AT26: Psychosurgery Modifiers (p. 232)
U27: Encountering Exsurgent life forms | AO27: 1d10+3 | AT27: Situation | BR27: Test Mod | BW27: SV Mod
A28: Other Important Topics | U28: Exsurgent virus infection | AO28: p. 366 | AT28: Improper Perparatory Diagnosis | BR28: -30 | BW28: +1
A29: Topic | P29: Page | U29: Witnessing psi-epsilon sleights | AO29: 1d10+2 | AT29: Safety Protocols Ignored | BR29: +20 | BW29: *2
A30: Acquiring Goods/Services | P30: p. 289 | AT30: Simulspace Time Acceleration | BR30: -20 | BW30: +2
A31: Complimentary Skills | P31: p. 173 | U31: Non-Physical Aptitude Tests (p. 175) | AT31: Subject is an AI, AGI, or Uplift | BR31: -20 | BW31: +1
A32: Derangements | P32: p. 210 | U32: Test | AI32: Roll
A33: Disorders | P33: p. 211 | U33: Composure and Resolve | AI33: WIL x3 | AT33: Psychosurgery Mechanics (p. 230)
A34: Game Rules Summary | P34: p. 127 | U34: Having An Idea | AI34: INT x3 or COG x3 | AT34: Success | BO34: Duration
A35: Hacking | P35: p. 393 | U35: Memorizing/Remembering | AI35: COG x3 | AT35: Psychosurgeon Succeeds/Patient Fails | BO35: Permanent
A36: Healing | P36: p. 208 | AT36: Psychosurgeon Succeeds Higher | BO36: Temporary: 1 week/MoS
A37: Hostile Environments | P37: p. 200 | AT37: Psychosurgeon Succeeds Lower/Fails | BO37: No effect
A38: Mental Healing/Psychotherapy | P38: p. 215
A39: Mesh Gear Quality | P39: p. 247
A40: Object/Synthmorph Repair | P40: p. 208
...

Sheet Credits
A1: Credits go out to; Rob Boyle and Transhuman Studios for Eclipse Phase and related texts Fiona Moore for laying the groundwork for this character sheet XB-88A for creating and developing The Sundered Galaxy setting Alerana Lasserin for contributions to TSG Engineer Raysh for contributions to TSG Ashes Darius for, well, she knows Shizuka K. for contributions to TSG A bunch of others for various and sundry contributions That fucking asshole that modified this shit-tier sheet from Fiona's initial contribution Revision History: Uhm, some time ago, Fiona Moore created the basic sheet. v. 1 Some time later, Zath modified the basic sheet to v. 1.2 or some shit, to include front-page rezpoint tabulations and so on, plus restructuring After that, the present version, effectively v. 2.0 is as it is seen now. Now includes Specialization autotabulation and automated Bio vs. Synth DUR tabulation. v.2.1 now includes autocalculation for Aptitude Costs taken from the Front Page, streamlined Moxie Costs and totals, automatic conversion of CP overages to RP costs, in addition to Idiot Lights for RP costs and Aptitude Points on the front page. Fantasy Phase effectively becomes Sheet Ver. 3; This features a greatly-condensed spreadsheet format, cutting down on the amount of tabbing. It also features something neat and never seen before in this line of sheets; On-the-fly adjustment of skills according to what you select for the attribute. This will eventually serve as an Eclipse Phase(1e) ver. 3.1 sheet basis, but for now it is operational for Fantasy PhaseFar Kingdoms purposes. You're welcome, people. Whelp, this is it. This is Eclipse Phase Sheet Ver. 3.0.
